Workbook

Sheet Kalkulator
B1: KALKULATOR PESANGON PHK
B2: Berdasarkan UU Cipta Kerja & PP No. 35 Tahun 2021 | Isi sel berwarna kuning
B4: 1 DATA KARYAWAN & UPAH
B5: Nama Karyawan | D5: Ilham
B6: Upah Pokok (Rp/bulan) | D6: 7500000
B7: Tunjangan Tetap (Rp/bulan) | D7: 0
B8: Upah Dasar Pesangon (Rp) | D8: =D6+D7 -> 7500000
B9: Masa Kerja - Tahun | D9: 2
B10: Masa Kerja - Bulan (0-11) | D10: 1
B11: Total Masa Kerja (tahun) | D11: =D9+D10/12 -> 2.0833333
B12: Alasan PHK (pilih dari daftar) | D12: Perusahaan tutup karena force majeure
B14: 2 INPUT UANG PENGGANTIAN HAK (UPH)
B15: Sisa Cuti Tahunan (hari) | D15: 7
B16: Pembagi Upah Harian (default 25) | D16: 25
B17: Nilai Penggantian Cuti (Rp) | D17: =IF(D16=0,0,D15*(D8/D16)) -> 2100000
B18: Biaya/Ongkos Pulang (Rp) | D18: 0
B19: Hak Lain sesuai PK/PP/PKB (Rp) | D19: 0
B20: Uang Pisah (Rp) - jika berlaku | D20: 0
B22: 3 PARAMETER OTOMATIS (terbaca dari Tabel Acuan)
B23: Pengali bulan UP (dari masa kerja) | D23: =IFERROR(VLOOKUP(D11,'Tabel Acuan'!$A$3:$B$11,2,TRUE()),0) -> 3
B24: Pengali bulan UPMK (dari masa kerja) | D24: =IFERROR(VLOOKUP(D11,'Tabel Acuan'!$D$3:$E$11,2,TRUE()),0) -> 0
B25: Faktor pengali UP (dari alasan PHK) | D25: =IFERROR(VLOOKUP(D12,'Tabel Acuan'!$B$16:$F$39,2,FALSE()),0) -> 0.5
B26: Faktor pengali UPMK (dari alasan PHK) | D26: =IFERROR(VLOOKUP(D12,'Tabel Acuan'!$B$16:$F$39,3,FALSE()),0) -> 1
B27: Uang pisah berlaku? | D27: =IFERROR(VLOOKUP(D12,'Tabel Acuan'!$B$16:$F$39,4,FALSE()),"-") -> Tidak
B29: 4 HASIL PERHITUNGAN
B30: Komponen | C30: Dasar Perhitungan | D30: Jumlah (Rp)
B31: Uang Pesangon (UP) | C31: ="Upah x "&D23&" bln x "&TEXT(D25,"0.##")&" pengali" -> Upah x 3 bln x 01 pengali | D31: =D8*D23*D25 -> 11250000
B32: Uang Penghargaan Masa Kerja (UPMK) | C32: ="Upah x "&D24&" bln x "&TEXT(D26,"0.##")&" pengali" -> Upah x 0 bln x 01 pengali | D32: =D8*D24*D26 -> 0
B33: UPH - Penggantian Cuti | C33: =D15&" hari x upah harian" -> 7 hari x upah harian | D33: =D17 -> 2100000
B34: UPH - Ongkos Pulang | C34: Input manual | D34: =D18 -> 0
B35: UPH - Hak Lain (PK/PP/PKB) | C35: Input manual | D35: =D19 -> 0
B36: Uang Pisah | C36: =IF(D27="Ya","Berlaku (input manual)","Tidak berlaku") -> Tidak berlaku | D36: =IF(D27="Ya",D20,0) -> 0
B37: TOTAL BRUTO YANG DIBAYARKAN | C37: Jumlah seluruh komponen di atas | D37: =SUM(D31:D36) -> 13350000
B39: Estimasi PPh 21 Final (potongan) | C39: PP 68/2009: 0%/5%/15%/25% berjenjang | D39: =MAX(0,MIN(D37,100000000)-50000000)*0.05+MAX(0,MIN(D37,500000000)-100000000)*0.15+MAX(0,D37-500000000)*0.25 -> 0
B40: TOTAL NETO DITERIMA KARYAWAN | C40: Total bruto - estimasi pajak | D40: =D37-D39 -> 13350000
B42: • Cara pakai: isi sel KUNING (upah, masa kerja, pilih alasan PHK dari dropdown, komponen UPH). Hasil terhitung otomatis.
B43: • Upah dasar = upah pokok + tunjangan tetap. Tunjangan tidak tetap (uang makan/transport berbasis kehadiran) TIDAK dihitung.
B44: • Penggantian cuti default = sisa cuti x (upah bulanan / 25). Ubah pembagi bila kebijakan perusahaan berbeda.
B45: • Uang pisah hanya dibayar untuk skenario tertentu (resign, mangkir, pelanggaran berat, dll) dan besarannya per PK/PP/PKB.
B46: • Estimasi PPh 21 berlaku bila pesangon dibayar sekaligus (dalam 2 tahun). Konsultasikan dengan konsultan pajak/hukum untuk kasus riil.
...

Sheet Tabel Acuan
A1: TABEL UANG PESANGON (UP) | D1: TABEL PENGHARGAAN MASA KERJA (UPMK)
A2: Masa kerja (thn, batas bawah) | B2: Pengali (bulan upah) | D2: Masa kerja (thn, batas bawah) | E2: Pengali (bulan upah)
A3: 0 | B3: 1 | D3: 0 | E3: 0
A4: 1 | B4: 2 | D4: 3 | E4: 2
A5: 2 | B5: 3 | D5: 6 | E5: 3
A6: 3 | B6: 4 | D6: 9 | E6: 4
A7: 4 | B7: 5 | D7: 12 | E7: 5
A8: 5 | B8: 6 | D8: 15 | E8: 6
A9: 6 | B9: 7 | D9: 18 | E9: 7
A10: 7 | B10: 8 | D10: 21 | E10: 8
A11: 8 | B11: 9 | D11: 24 | E11: 10
A14: TABEL FAKTOR PENGALI BERDASARKAN ALASAN PHK (PP No. 35 Tahun 2021)
A15: No | B15: Alasan PHK | C15: Pengali UP | D15: Pengali UPMK | E15: Uang Pisah | F15: Catatan
A16: 1 | B16: Penggabungan/peleburan/pengambilalihan - pekerja tidak lanjut | C16: 1 | D16: 1 | E16: Tidak | F16: Pekerja tidak bersedia melanjutkan
A17: 2 | B17: Pengambilalihan - syarat kerja berubah, pekerja menolak | C17: 0.5 | D17: 1 | E17: Tidak | F17: Hanya jika pekerja menolak syarat baru
A18: 3 | B18: Efisiensi akibat kerugian | C18: 0.5 | D18: 1 | E18: Tidak | F18: Kerugian harus dibuktikan (audit)
A19: 4 | B19: Efisiensi untuk mencegah kerugian | C19: 1 | D19: 1 | E19: Tidak | F19: Pencegahan kerugian
A20: 5 | B20: Perusahaan tutup karena rugi terus-menerus 2 tahun | C20: 0.5 | D20: 1 | E20: Tidak | F20: Tutup karena rugi
A21: 6 | B21: Perusahaan tutup bukan karena rugi | C21: 1 | D21: 1 | E21: Tidak | F21: Tutup bukan karena rugi
A22: 7 | B22: Perusahaan tutup karena force majeure | C22: 0.5 | D22: 1 | E22: Tidak | F22: Bencana/keadaan memaksa
A23: 8 | B23: Force majeure tanpa penutupan perusahaan | C23: 0.75 | D23: 1 | E23: Tidak | F23: Perusahaan tetap beroperasi
A24: 9 | B24: PKPU karena perusahaan rugi | C24: 0.5 | D24: 1 | E24: Tidak | F24: Penundaan kewajiban pembayaran utang
A25: 10 | B25: PKPU bukan karena perusahaan rugi | C25: 1 | D25: 1 | E25: Tidak | F25: Penundaan kewajiban pembayaran utang
A26: 11 | B26: Perusahaan pailit | C26: 0.5 | D26: 1 | E26: Tidak | F26: Dinyatakan pailit oleh pengadilan
A27: 12 | B27: Permohonan PHK oleh pekerja (pengusaha melanggar) | C27: 1 | D27: 1 | E27: Tidak | F27: Pengusaha terbukti melanggar hak pekerja
... A39: 24 | B39: Pekerja meninggal dunia | C39: 2 | D39: 1 | E39: Tidak | F39: Dibayarkan kepada ahli waris
A41: • Dasar perhitungan upah = upah pokok + tunjangan tetap (UU Cipta Kerja).
A42: • Maksimal UP = 9 bulan upah; maksimal UPMK = 10 bulan upah. UPMK hanya untuk masa kerja minimal 3 tahun.
A43: • UPH selalu dibayarkan: sisa cuti tahunan, ongkos pulang pekerja+keluarga, dan hak lain sesuai PK/PP/PKB.
A44: • Uang pisah besarannya ditetapkan dalam PK/PP/PKB perusahaan (diisi manual pada sheet Kalkulator).
A45: • Ketentuan ini bersifat MINIMUM. Perusahaan boleh memberi lebih besar lewat PKB (Putusan MK 168/2023).
